tests/fixtures/resync_scenario.json
[
  {
    "e": "depthUpdate",
    "E": 1234567891000,
    "T": 1234567891000,
    "s": "BTCUSDT",
    "U": 151,
    "u": 155,
    "pu": 150,
    "b": [["50000.10", "2.000"]],
    "a": [["50000.20", "1.000"]]
  },
  {
    "e": "depthUpdate",
    "E": 1234567892000,
    "T": 1234567892000,
    "s": "BTCUSDT",
    "U": 156,
    "u": 160,
    "pu": 155,
    "b": [["50000.00", "3.000"]],
    "a": [["50000.50", "2.000"]]
  },
  {
    "e": "depthUpdate",
    "E": 1234567893000,
    "T": 1234567893000,
    "s": "BTCUSDT",
    "U": 161,
    "u": 165,
    "pu": 160,
    "b": [["49999.90", "1.500"]],
    "a": [["50001.00", "0.800"]]
  }
]
